<?xml version='1.0'?>
<sdf version='1.6'>
  <model name='TEO_trunk'>

    <link name='AxialWaist_link'>
      <pose>0 0 0 0 -0 0</pose>
      <inertial>
        <pose>-0.002235 -0.000979 -0.018814 0 -0 0</pose>
        <mass>1</mass>
        <inertia>
          <ixx>0.001977587</ixx>
          <ixy>0.00000206</ixy>
          <ixz>0.0000297</ixz>
          <iyy>0.000899729</iyy>
          <iyz>-0.00000307</iyz>
          <izz>0.001471749</izz>
        </inertia>
      </inertial>
      <visual name='AxialWaist_visual'>
        <geometry>
          <mesh>
            <uri>model://teo/meshes/visual/AxialWaist.dae</uri>
          </mesh>
        </geometry>
      </visual>
    </link>

    <joint name='AxialWaist' type='revolute'>
      <parent>TEO::RootWaist_links</parent>
      <child>TEO_trunk::AxialWaist_link</child>
      <axis>
        <xyz>0 0 1</xyz>
        <limit>
          <lower>-1.03</lower>
          <upper>0.81</upper>
        </limit>
      </axis>
    </joint>

    <link name='FrontalWaist_link'>
      <pose>0 0 0 0 -0 0</pose>
      <inertial>
        <pose>0.032985 -0.007876 0.220667 0 -0 0</pose>
        <mass>14.23545</mass>
        <inertia>
          <ixx>0.33566514</ixx>
          <ixy>0.000162127</ixy>
          <ixz>0.011858221</ixz>
          <iyy>0.126531585</iyy>
          <iyz>0.000914091</iyz>
          <izz>0.263359225</izz>
        </inertia>
      </inertial>
      <visual name='FrontalWaist_visual'>
        <geometry>
          <mesh>
            <uri>model://teo/meshes/visual/RootWaist.dae</uri>
          </mesh>
        </geometry>
      </visual>
    </link>

    <joint name='FrontalWaist' type='revolute'>
      <parent>TEO_trunk::AxialWaist_link</parent>
      <child>TEO_trunk::FrontalWaist_link</child>
      <axis>
        <xyz>0 1 0</xyz>
        <limit>
          <lower>-1.58</lower>
          <upper>0.18</upper>
        </limit>
      </axis>
    </joint>

    <plugin name='controlboard_trunk' filename='libgazebo_yarp_controlboard.so'>
      <yarpConfigurationFile>model://teo/conf/gazebo_teo_trunk.ini</yarpConfigurationFile>
    </plugin>

  </model>
</sdf>
