<?xml version='1.0'?>
<sdf version='1.6'>
  <model name='teo_leftLeg'>

    <link name='AxialLeftHip_link'>
      <pose>0 0 0 0 -0 0</pose>
      <visual name='AxialLeftHip_visual'>
        <geometry>
          <mesh>
            <uri>model://teo/daes/AxialLeftHip.dae</uri>
          </mesh>
        </geometry>
      </visual>
    </link>

    <joint name='AxialLeftHip' type='revolute'>
      <parent>teo::RootWaist_links</parent>
      <child>teo_leftLeg::AxialLeftHip_link</child>
      <axis>
        <xyz>0 0 1</xyz>
        <limit>
          <lower>-0.49</lower>
          <upper>0.57</upper>
        </limit>
      </axis>
    </joint>

    <link name='SagittalLeftHip_link'>
      <pose>0 0 -0.092 0 -0 0</pose>
      <visual name='SagittalLeftHip_visual'>
        <geometry>
          <mesh>
            <uri>model://teo/daes/SagittalLeftHip.dae</uri>
          </mesh>
        </geometry>
      </visual>
    </link>

    <joint name='SagittalLeftHip' type='revolute'>
      <parent>teo_leftLeg::AxialLeftHip_link</parent>
      <child>teo_leftLeg::SagittalLeftHip_link</child>
      <axis>
        <xyz>1 0 0</xyz>
        <limit>
          <lower>-0.22</lower>
          <upper>0.25</upper>
        </limit>
      </axis>
    </joint>

    <link name='FrontalLeftHip_link'>
      <pose>0 0 -0.092 0 -0 0</pose>
      <visual name='FrontalLeftHip_visual'>
        <geometry>
          <mesh>
            <uri>model://teo/daes/FrontalLeftHip.dae</uri>
          </mesh>
        </geometry>
      </visual>
    </link>

    <joint name='FrontalLeftHip' type='revolute'>
      <parent>teo_leftLeg::SagittalLeftHip_link</parent>
      <child>teo_leftLeg::FrontalLeftHip_link</child>
      <axis>
        <xyz>0 1 0</xyz>
        <limit>
          <lower>-0.55</lower>
          <upper>0.74</upper>
        </limit>
      </axis>
    </joint>

    <link name='FrontalLeftKnee_link'>
      <pose>0 0 -0.33 0 -0 0</pose>
      <visual name='FrontalLeftKnee_visual'>
        <geometry>
          <mesh>
            <uri>model://teo/daes/FrontalLeftKnee.dae</uri>
          </mesh>
        </geometry>
      </visual>
    </link>

    <joint name='FrontalLeftKnee' type='revolute'>
      <parent>teo_leftLeg::FrontalLeftHip_link</parent>
      <child>teo_leftLeg::FrontalLeftKnee_link</child>
      <axis>
        <xyz>0 1 0</xyz>
        <limit>
          <lower>-1.07</lower>
          <upper>1.44</upper>
        </limit>
      </axis>
    </joint>

    <link name='FrontalLeftAnkle_link'>
      <pose>0 -0.0175 -0.63 0 -0 0</pose>
      <visual name='FrontalLeftAnkle_visual'>
        <geometry>
          <mesh>
            <uri>model://teo/daes/FrontalLeftAnkle.dae</uri>
          </mesh>
        </geometry>
      </visual>
    </link>

    <joint name='FrontalLeftAnkle' type='revolute'>
      <parent>teo_leftLeg::FrontalLeftKnee_link</parent>
      <child>teo_leftLeg::FrontalLeftAnkle_link</child>
      <axis>
        <xyz>0 1 0</xyz>
        <limit>
          <lower>-0.4</lower>
          <upper>0.44</upper>
        </limit>
      </axis>
    </joint>

    <link name='SagittalLeftAnkle_link'>
      <pose>0 -0.0175 -0.63 0 -0 0</pose>
      <visual name='SagittalLeftAnkle_visual'>
        <geometry>
          <mesh>
            <uri>model://teo/daes/SagittalLeftAnkle.dae</uri>
          </mesh>
        </geometry>
      </visual>
    </link>

    <joint name='SagittalLeftAnkle' type='revolute'>
      <parent>teo_leftLeg::FrontalLeftAnkle_link</parent>
      <child>teo_leftLeg::SagittalLeftAnkle_link</child>
      <axis>
        <xyz>1 0 0</xyz>
        <limit>
          <lower>-0.74</lower>
          <upper>0.35</upper>
        </limit>
      </axis>
    </joint>

    <plugin name='controlboard_leftLeg' filename='libgazebo_yarp_controlboard.so'>
      <yarpConfigurationFile>model://teo/conf/gazebo_teo_leftLeg.ini</yarpConfigurationFile>
    </plugin>

  </model>
</sdf>
