<?xml version='1.0'?>
<sdf version='1.6'>
  <model name='teo'>

    <!-- TRUNK -->

    <link name='RootWaist_links'>
      <pose>0 0 0 0 -0 0</pose>
      <visual name='RootWaist_links_visual'>
        <geometry>
          <mesh>
            <uri>model://teo/daes/RootWaist_links.dae</uri>
          </mesh>
        </geometry>
      </visual>
    </link>

    <link name='AxialWaist_link'>
      <pose>0 0 0.1932 0 -0 0</pose>
      <visual name='AxialWaist_visual'>
        <geometry>
          <mesh>
            <uri>model://teo/daes/AxialWaist.dae</uri>
          </mesh>
        </geometry>
      </visual>
    </link>

    <joint name='AxialWaist' type='revolute'>
      <parent>RootWaist_links</parent>
      <child>AxialWaist_link</child>
      <axis>
        <xyz>0 0 1</xyz>
        <limit>
          <lower>-1.03</lower>
          <upper>0.81</upper>
        </limit>
      </axis>
    </joint>

    <link name='FrontalWaist_link'>
      <pose>0 0 0.1932 0 -0 0</pose>
      <visual name='FrontalWaist_visual'>
        <geometry>
          <mesh>
            <uri>model://teo/daes/RootWaist.dae</uri>
          </mesh>
        </geometry>
      </visual>
    </link>

    <joint name='FrontalWaist' type='revolute'>
      <parent>AxialWaist_link</parent>
      <child>FrontalWaist_link</child>
      <axis>
        <xyz>0 1 0</xyz>
        <limit>
          <lower>-1.58</lower>
          <upper>0.18</upper>
        </limit>
      </axis>
    </joint>

    <!-- HEAD -->

    <link name='AxialNeck_link'>
      <pose>0 0 0.6282 0 -0 0</pose>
      <visual name='AxialNeck_visual'>
        <geometry>
          <mesh>
            <uri>model://teo/daes/AxialNeck.dae</uri>
          </mesh>
        </geometry>
      </visual>
    </link>

    <joint name='AxialNeck' type='revolute'>
      <parent>FrontalWaist_link</parent>
      <child>AxialNeck_link</child>
      <axis>
        <xyz>0 0 1</xyz>
        <limit>
          <lower>-1.22</lower>
          <upper>1.22</upper>
        </limit>
      </axis>
    </joint>

    <link name='FrontalNeck_link'>
      <pose>0 0 0.6607 0 -0 0</pose>
      <visual name='FrontalNeck_visual'>
        <geometry>
          <mesh>
            <uri>model://teo/daes/FrontalNeck.dae</uri>
          </mesh>
        </geometry>
      </visual>
    </link>

    <joint name='FrontalNeck' type='revolute'>
      <parent>AxialNeck_link</parent>
      <child>FrontalNeck_link</child>
      <axis>
        <xyz>0 1 0</xyz>
        <limit>
          <lower>-0.51</lower>
          <upper>0.15</upper>
        </limit>
      </axis>
    </joint>

    <!-- RIGHT ARM -->

    <link name='FrontalRightShoulder_link'>
      <pose>0 -0.26292 0.4982 0 -0 0</pose>
      <visual name='FrontalRightShoulder_visual'>
        <geometry>
          <mesh>
            <uri>model://teo/daes/FrontalRightShoulder.dae</uri>
          </mesh>
        </geometry>
      </visual>
    </link>

    <joint name='FrontalRightShoulder' type='revolute'>
      <parent>FrontalWaist_link</parent>
      <child>FrontalRightShoulder_link</child>
      <axis>
        <xyz>0 1 0</xyz>
        <limit>
          <lower>-1.71</lower>
          <upper>1.85</upper>
        </limit>
      </axis>
    </joint>

    <link name='SagittalRightShoulder_link'>
      <pose>0 -0.34692 0.4982 0 -0 0</pose>
      <visual name='SagittalRightShoulder_visual'>
        <geometry>
          <mesh>
            <uri>model://teo/daes/SagittalRightShoulder.dae</uri>
          </mesh>
        </geometry>
      </visual>
    </link>

    <joint name='SagittalRightShoulder' type='revolute'>
      <parent>FrontalRightShoulder_link</parent>
      <child>SagittalRightShoulder_link</child>
      <axis>
        <xyz>1 0 0</xyz>
        <limit>
          <lower>-1.32</lower>
          <upper>0.39</upper>
        </limit>
      </axis>
    </joint>

    <link name='AxialRightShoulder_link'>
      <pose>0 -0.34692 0.1692 0 -0 0</pose>
      <visual name='AxialRightShoulder_visual'>
        <geometry>
          <mesh>
            <uri>model://teo/daes/AxialRightShoulder.dae</uri>
          </mesh>
        </geometry>
      </visual>
    </link>

    <joint name='AxialRightShoulder' type='revolute'>
      <parent>SagittalRightShoulder_link</parent>
      <child>AxialRightShoulder_link</child>
      <axis>
        <xyz>0 0 1</xyz>
        <limit>
          <lower>-1.4</lower>
          <upper>0.99</upper>
        </limit>
      </axis>
    </joint>

    <link name='FrontalRightElbow_link'>
      <pose>0 -0.34692 0.1692 0 -0 0</pose>
      <visual name='FrontalRightElbow_visual'>
        <geometry>
          <mesh>
            <uri>model://teo/daes/FrontalRightElbow.dae</uri>
          </mesh>
        </geometry>
      </visual>
    </link>

    <joint name='FrontalRightElbow' type='revolute'>
      <parent>AxialRightShoulder_link</parent>
      <child>FrontalRightElbow_link</child>
      <axis>
        <xyz>0 1 0</xyz>
        <limit>
          <lower>-1.74</lower>
          <upper>1.72</upper>
        </limit>
      </axis>
    </joint>

    <link name='AxialRightWrist_link'>
      <pose>0 -0.34692 -0.0328 0 -0 0</pose>
      <visual name='AxialRightWrist_visual'>
        <geometry>
          <mesh>
            <uri>model://teo/daes/AxialRightWrist.dae</uri>
          </mesh>
        </geometry>
      </visual>
    </link>

    <joint name='AxialRightWrist' type='revolute'>
      <parent>FrontalRightElbow_link</parent>
      <child>AxialRightWrist_link</child>
      <axis>
        <xyz>0 0 1</xyz>
        <limit>
          <lower>-1.4</lower>
          <upper>1.74</upper>
        </limit>
      </axis>
    </joint>

    <link name='FrontalRightWrist_link'>
      <pose>0 -0.34692 -0.0328 0 -0 0</pose>
      <visual name='FrontalRightWrist_visual'>
        <geometry>
          <mesh>
            <uri>model://teo/daes/FrontalRightWrist.dae</uri>
          </mesh>
        </geometry>
      </visual>
    </link>

    <joint name='FrontalRightWrist' type='revolute'>
      <parent>AxialRightWrist_link</parent>
      <child>FrontalRightWrist_link</child>
      <axis>
        <xyz>0 1 0</xyz>
        <limit>
          <lower>-2.01</lower>
          <upper>0.78</upper>
        </limit>
      </axis>
    </joint>

    <!-- LEFT ARM -->

    <link name='FrontalLeftShoulder_link'>
      <pose>0 0.26292 0.4982 0 -0 0</pose>
      <visual name='FrontalLeftShoulder_visual'>
        <geometry>
          <mesh>
            <uri>model://teo/daes/FrontalLeftShoulder.dae</uri>
          </mesh>
        </geometry>
      </visual>
    </link>

    <joint name='FrontalLeftShoulder' type='revolute'>
      <parent>FrontalWaist_link</parent>
      <child>FrontalLeftShoulder_link</child>
      <axis>
        <xyz>0 1 0</xyz>
        <limit>
          <lower>-1.69</lower>
          <upper>1.98</upper>
        </limit>
      </axis>
    </joint>

    <link name='SagittalLeftShoulder_link'>
      <pose>0 0.34692 0.4982 0 -0 0</pose>
      <visual name='SagittalLeftShoulder_visual'>
        <geometry>
          <mesh>
            <uri>model://teo/daes/SagittalLeftShoulder.dae</uri>
          </mesh>
        </geometry>
      </visual>
    </link>

    <joint name='SagittalLeftShoulder' type='revolute'>
      <parent>FrontalLeftShoulder_link</parent>
      <child>SagittalLeftShoulder_link</child>
      <axis>
        <xyz>1 0 0</xyz>
        <limit>
          <lower>-0.42</lower>
          <upper>1.34</upper>
        </limit>
      </axis>
    </joint>

    <link name='AxialLeftShoulder_link'>
      <pose>0 0.34692 0.1692 0 -0 0</pose>
      <visual name='AxialLeftShoulder_visual'>
        <geometry>
          <mesh>
            <uri>model://teo/daes/AxialLeftShoulder.dae</uri>
          </mesh>
        </geometry>
      </visual>
    </link>

    <joint name='AxialLeftShoulder' type='revolute'>
      <parent>SagittalLeftShoulder_link</parent>
      <child>AxialLeftShoulder_link</child>
      <axis>
        <xyz>0 0 1</xyz>
        <limit>
          <lower>-0.9</lower>
          <upper>1.47</upper>
        </limit>
      </axis>
    </joint>

    <link name='FrontalLeftElbow_link'>
      <pose>0 0.34692 0.1692 0 -0 0</pose>
      <visual name='FrontalLeftElbow_visual'>
        <geometry>
          <mesh>
            <uri>model://teo/daes/FrontalLeftElbow.dae</uri>
          </mesh>
        </geometry>
      </visual>
    </link>

    <joint name='FrontalLeftElbow' type='revolute'>
      <parent>AxialLeftShoulder_link</parent>
      <child>FrontalLeftElbow_link</child>
      <axis>
        <xyz>0 1 0</xyz>
        <limit>
          <lower>-1.76</lower>
          <upper>1.69</upper>
        </limit>
      </axis>
    </joint>

    <link name='AxialLeftWrist_link'>
      <pose>0 0.34692 -0.0328 0 -0 0</pose>
      <visual name='AxialLeftWrist_visual'>
        <geometry>
          <mesh>
            <uri>model://teo/daes/AxialLeftWrist.dae</uri>
          </mesh>
        </geometry>
      </visual>
    </link>

    <joint name='AxialLeftWrist' type='revolute'>
      <parent>FrontalLeftElbow_link</parent>
      <child>AxialLeftWrist_link</child>
      <axis>
        <xyz>0 0 1</xyz>
        <limit>
          <lower>-1.77</lower>
          <upper>1.33</upper>
        </limit>
      </axis>
    </joint>

    <link name='FrontalLeftWrist_link'>
      <pose>0 0.34692 -0.0328 0 -0 0</pose>
      <visual name='FrontalLeftWrist_visual'>
        <geometry>
          <mesh>
            <uri>model://teo/daes/FrontalLeftWrist.dae</uri>
          </mesh>
        </geometry>
      </visual>
    </link>

    <joint name='FrontalLeftWrist' type='revolute'>
      <parent>AxialLeftWrist_link</parent>
      <child>FrontalLeftWrist_link</child>
      <axis>
        <xyz>0 1 0</xyz>
        <limit>
          <lower>-1.98</lower>
          <upper>1.07</upper>
        </limit>
      </axis>
    </joint>

    <!-- RIGHT LEG -->

    <link name='AxialRightHip_link'>
      <pose>0 -0.146 0 0 -0 0</pose>
      <visual name='AxialRightHip_visual'>
        <geometry>
          <mesh>
            <uri>model://teo/daes/AxialRightHip.dae</uri>
          </mesh>
        </geometry>
      </visual>
    </link>

    <joint name='AxialRightHip' type='revolute'>
      <parent>RootWaist_links</parent>
      <child>AxialRightHip_link</child>
      <axis>
        <xyz>0 0 1</xyz>
        <limit>
          <lower>-0.57</lower>
          <upper>0.49</upper>
        </limit>
      </axis>
    </joint>

    <link name='SagittalRightHip_link'>
      <pose>0 -0.146 -0.092 0 -0 0</pose>
      <visual name='SagittalRightHip_visual'>
        <geometry>
          <mesh>
            <uri>model://teo/daes/SagittalRightHip.dae</uri>
          </mesh>
        </geometry>
      </visual>
    </link>

    <joint name='SagittalRightHip' type='revolute'>
      <parent>AxialRightHip_link</parent>
      <child>SagittalRightHip_link</child>
      <axis>
        <xyz>1 0 0</xyz>
        <limit>
          <lower>-0.25</lower>
          <upper>0.22</upper>
        </limit>
      </axis>
    </joint>

    <link name='FrontalRightHip_link'>
      <pose>0 -0.146 -0.092 0 -0 0</pose>
      <visual name='FrontalRightHip_visual'>
        <geometry>
          <mesh>
            <uri>model://teo/daes/FrontalRightHip.dae</uri>
          </mesh>
        </geometry>
      </visual>
    </link>

    <joint name='FrontalRightHip' type='revolute'>
      <parent>SagittalRightHip_link</parent>
      <child>FrontalRightHip_link</child>
      <axis>
        <xyz>0 1 0</xyz>
        <limit>
          <lower>-0.55</lower>
          <upper>0.74</upper>
        </limit>
      </axis>
    </joint>

    <link name='FrontalRightKnee_link'>
      <pose>0 -0.146 -0.422 0 -0 0</pose>
      <visual name='FrontalRightKnee_visual'>
        <geometry>
          <mesh>
            <uri>model://teo/daes/FrontalRightKnee.dae</uri>
          </mesh>
        </geometry>
      </visual>
    </link>

    <joint name='FrontalRightKnee' type='revolute'>
      <parent>FrontalRightHip_link</parent>
      <child>FrontalRightKnee_link</child>
      <axis>
        <xyz>0 1 0</xyz>
        <limit>
          <lower>-1.07</lower>
          <upper>1.44</upper>
        </limit>
      </axis>
    </joint>

    <link name='FrontalRightAnkle_link'>
      <pose>0 -0.1285 -0.722 0 -0 0</pose>
      <visual name='FrontalRightAnkle_visual'>
        <geometry>
          <mesh>
            <uri>model://teo/daes/FrontalRightAnkle.dae</uri>
          </mesh>
        </geometry>
      </visual>
    </link>

    <joint name='FrontalRightAnkle' type='revolute'>
      <parent>FrontalRightKnee_link</parent>
      <child>FrontalRightAnkle_link</child>
      <axis>
        <xyz>0 1 0</xyz>
        <limit>
          <lower>-0.4</lower>
          <upper>0.44</upper>
        </limit>
      </axis>
    </joint>

    <link name='SagittalRightAnkle_link'>
      <pose>0 -0.1285 -0.722 0 -0 0</pose>
      <visual name='FrontalRightAnkle_visual'>
        <geometry>
          <mesh>
            <uri>model://teo/daes/SagittalRightAnkle.dae</uri>
          </mesh>
        </geometry>
      </visual>
    </link>

    <joint name='SagittalRightAnkle' type='revolute'>
      <parent>FrontalRightAnkle_link</parent>
      <child>SagittalRightAnkle_link</child>
      <axis>
        <xyz>1 0 0</xyz>
        <limit>
          <lower>-0.35</lower>
          <upper>0.74</upper>
        </limit>
      </axis>
    </joint>

    <!-- LEFT LEG -->

    <link name='AxialLeftHip_link'>
      <pose>0 0.146 0 0 -0 0</pose>
      <visual name='AxialLeftHip_visual'>
        <geometry>
          <mesh>
            <uri>model://teo/daes/AxialLeftHip.dae</uri>
          </mesh>
        </geometry>
      </visual>
    </link>

    <joint name='AxialLeftHip' type='revolute'>
      <parent>RootWaist_links</parent>
      <child>AxialLeftHip_link</child>
      <axis>
        <xyz>0 0 1</xyz>
        <limit>
          <lower>-0.49</lower>
          <upper>0.57</upper>
        </limit>
      </axis>
    </joint>

    <link name='SagittalLeftHip_link'>
      <pose>0 0.146 -0.092 0 -0 0</pose>
      <visual name='SagittalLeftHip_visual'>
        <geometry>
          <mesh>
            <uri>model://teo/daes/SagittalLeftHip.dae</uri>
          </mesh>
        </geometry>
      </visual>
    </link>

    <joint name='SagittalLeftHip' type='revolute'>
      <parent>AxialLeftHip_link</parent>
      <child>SagittalLeftHip_link</child>
      <axis>
        <xyz>1 0 0</xyz>
        <limit>
          <lower>-0.22</lower>
          <upper>0.25</upper>
        </limit>
      </axis>
    </joint>

    <link name='FrontalLeftHip_link'>
      <pose>0 0.146 -0.092 0 -0 0</pose>
      <visual name='FrontalLeftHip_visual'>
        <geometry>
          <mesh>
            <uri>model://teo/daes/FrontalLeftHip.dae</uri>
          </mesh>
        </geometry>
      </visual>
    </link>

    <joint name='FrontalLeftHip' type='revolute'>
      <parent>SagittalLeftHip_link</parent>
      <child>FrontalLeftHip_link</child>
      <axis>
        <xyz>0 1 0</xyz>
        <limit>
          <lower>-0.55</lower>
          <upper>0.74</upper>
        </limit>
      </axis>
    </joint>

    <link name='FrontalLeftKnee_link'>
      <pose>0 0.146 -0.422 0 -0 0</pose>
      <visual name='FrontalLeftKnee_visual'>
        <geometry>
          <mesh>
            <uri>model://teo/daes/FrontalLeftKnee.dae</uri>
          </mesh>
        </geometry>
      </visual>
    </link>

    <joint name='FrontalLeftKnee' type='revolute'>
      <parent>FrontalLeftHip_link</parent>
      <child>FrontalLeftKnee_link</child>
      <axis>
        <xyz>0 1 0</xyz>
        <limit>
          <lower>-1.07</lower>
          <upper>1.44</upper>
        </limit>
      </axis>
    </joint>

    <link name='FrontalLeftAnkle_link'>
      <pose>0 0.1285 -0.722 0 -0 0</pose>
      <visual name='FrontalLeftAnkle_visual'>
        <geometry>
          <mesh>
            <uri>model://teo/daes/FrontalLeftAnkle.dae</uri>
          </mesh>
        </geometry>
      </visual>
    </link>

    <joint name='FrontalLeftAnkle' type='revolute'>
      <parent>FrontalLeftKnee_link</parent>
      <child>FrontalLeftAnkle_link</child>
      <axis>
        <xyz>0 1 0</xyz>
        <limit>
          <lower>-0.4</lower>
          <upper>0.44</upper>
        </limit>
      </axis>
    </joint>

    <link name='SagittalLeftAnkle_link'>
      <pose>0 0.1285 -0.722 0 -0 0</pose>
      <visual name='SagittalLeftAnkle_visual'>
        <geometry>
          <mesh>
            <uri>model://teo/daes/SagittalLeftAnkle.dae</uri>
          </mesh>
        </geometry>
      </visual>
    </link>

    <joint name='SagittalLeftAnkle' type='revolute'>
      <parent>FrontalLeftAnkle_link</parent>
      <child>SagittalLeftAnkle_link</child>
      <axis>
        <xyz>1 0 0</xyz>
        <limit>
          <lower>-0.74</lower>
          <upper>0.35</upper>
        </limit>
      </axis>
    </joint>

    <!-- PLUGINS -->

    <plugin name='controlboard_trunk' filename='libgazebo_yarp_controlboard.so'>
      <yarpConfigurationFile>model://teo/conf/gazebo_teo_trunk.ini</yarpConfigurationFile>
    </plugin>

    <plugin name='controlboard_head' filename='libgazebo_yarp_controlboard.so'>
      <yarpConfigurationFile>model://teo/conf/gazebo_teo_head.ini</yarpConfigurationFile>
    </plugin>

    <plugin name='controlboard_rightArm' filename='libgazebo_yarp_controlboard.so'>
      <yarpConfigurationFile>model://teo/conf/gazebo_teo_rightArm.ini</yarpConfigurationFile>
    </plugin>

    <plugin name='controlboard_leftArm' filename='libgazebo_yarp_controlboard.so'>
      <yarpConfigurationFile>model://teo/conf/gazebo_teo_leftArm.ini</yarpConfigurationFile>
    </plugin>

    <plugin name='controlboard_rightLeg' filename='libgazebo_yarp_controlboard.so'>
      <yarpConfigurationFile>model://teo/conf/gazebo_teo_rightLeg.ini</yarpConfigurationFile>
    </plugin>

    <plugin name='controlboard_leftLeg' filename='libgazebo_yarp_controlboard.so'>
      <yarpConfigurationFile>model://teo/conf/gazebo_teo_leftLeg.ini</yarpConfigurationFile>
    </plugin>

    <!-- MISCELLANEA -->

    <static>0</static>
    <enable_wind>0</enable_wind>
    <pose>0 0 0 0 -0 0</pose>
  </model>
</sdf>
