<?xml version='1.0'?>
<sdf version='1.6'>
  <model name='teo_leftArm'>

    <link name='FrontalLeftShoulder_link'>
      <pose>0 0 0 0 -0 0</pose>
      <visual name='FrontalLeftShoulder_visual'>
        <geometry>
          <mesh>
            <uri>model://teo/daes/FrontalLeftShoulder.dae</uri>
          </mesh>
        </geometry>
      </visual>
    </link>

    <joint name='FrontalLeftShoulder' type='revolute'>
      <parent>teo_trunk::FrontalWaist_link</parent>
      <child>teo_leftArm::FrontalLeftShoulder_link</child>
      <axis>
        <xyz>0 1 0</xyz>
        <limit>
          <lower>-1.69</lower>
          <upper>1.98</upper>
        </limit>
      </axis>
    </joint>

    <link name='SagittalLeftShoulder_link'>
      <pose>0 0.084 0 0 -0 0</pose>
      <visual name='SagittalLeftShoulder_visual'>
        <geometry>
          <mesh>
            <uri>model://teo/daes/SagittalLeftShoulder.dae</uri>
          </mesh>
        </geometry>
      </visual>
    </link>

    <joint name='SagittalLeftShoulder' type='revolute'>
      <parent>teo_leftArm::FrontalLeftShoulder_link</parent>
      <child>teo_leftArm::SagittalLeftShoulder_link</child>
      <axis>
        <xyz>1 0 0</xyz>
        <limit>
          <lower>-0.42</lower>
          <upper>1.34</upper>
        </limit>
      </axis>
    </joint>

    <link name='AxialLeftShoulder_link'>
      <pose>0 0.084 -0.329 0 -0 0</pose>
      <visual name='AxialLeftShoulder_visual'>
        <geometry>
          <mesh>
            <uri>model://teo/daes/AxialLeftShoulder.dae</uri>
          </mesh>
        </geometry>
      </visual>
    </link>

    <joint name='AxialLeftShoulder' type='revolute'>
      <parent>teo_leftArm::SagittalLeftShoulder_link</parent>
      <child>teo_leftArm::AxialLeftShoulder_link</child>
      <axis>
        <xyz>0 0 1</xyz>
        <limit>
          <lower>-0.9</lower>
          <upper>1.47</upper>
        </limit>
      </axis>
    </joint>

    <link name='FrontalLeftElbow_link'>
      <pose>0 0.084 -0.329 0 -0 0</pose>
      <visual name='FrontalLeftElbow_visual'>
        <geometry>
          <mesh>
            <uri>model://teo/daes/FrontalLeftElbow.dae</uri>
          </mesh>
        </geometry>
      </visual>
    </link>

    <joint name='FrontalLeftElbow' type='revolute'>
      <parent>teo_leftArm::AxialLeftShoulder_link</parent>
      <child>teo_leftArm::FrontalLeftElbow_link</child>
      <axis>
        <xyz>0 1 0</xyz>
        <limit>
          <lower>-1.76</lower>
          <upper>1.69</upper>
        </limit>
      </axis>
    </joint>

    <link name='AxialLeftWrist_link'>
      <pose>0 0.084 -0.531 0 -0 0</pose>
      <visual name='AxialLeftWrist_visual'>
        <geometry>
          <mesh>
            <uri>model://teo/daes/AxialLeftWrist.dae</uri>
          </mesh>
        </geometry>
      </visual>
    </link>

    <joint name='AxialLeftWrist' type='revolute'>
      <parent>teo_leftArm::FrontalLeftElbow_link</parent>
      <child>teo_leftArm::AxialLeftWrist_link</child>
      <axis>
        <xyz>0 0 1</xyz>
        <limit>
          <lower>-1.77</lower>
          <upper>1.33</upper>
        </limit>
      </axis>
    </joint>

    <link name='FrontalLeftWrist_link'>
      <pose>0 0.084 -0.531 0 -0 0</pose>
      <visual name='FrontalLeftWrist_visual'>
        <geometry>
          <mesh>
            <uri>model://teo/daes/FrontalLeftWrist.dae</uri>
          </mesh>
        </geometry>
      </visual>
    </link>

    <joint name='FrontalLeftWrist' type='revolute'>
      <parent>teo_leftArm::AxialLeftWrist_link</parent>
      <child>teo_leftArm::FrontalLeftWrist_link</child>
      <axis>
        <xyz>0 1 0</xyz>
        <limit>
          <lower>-1.98</lower>
          <upper>1.07</upper>
        </limit>
      </axis>
    </joint>

    <plugin name='controlboard_leftArm' filename='libgazebo_yarp_controlboard.so'>
      <yarpConfigurationFile>model://teo/conf/gazebo_teo_leftArm.ini</yarpConfigurationFile>
    </plugin>

  </model>
</sdf>
